<mujoco model='sawyer'>
    <compiler angle='radian' coordinate='local' />
	<option collision='all' impratio='5' cone='elliptic' timestep='0.001' gravity='0 0 -9.8' viscosity='0' iterations='20' />
    <size njmax='1500' nconmax='300' />

	<!--  ================= Visual Elements ================= /-->
	<asset>
		<material name='MatGnd' specular='.3' shininess='.3' reflectance='0.3' rgba='.5 .55 .5 1'/>
	</asset>

	<!--  ================= Physical Properties ================= /-->
	<default>
		<geom solref='0.01 1' solimp='0.95 0.95 0.01' condim='4'/>

		<default class='table'>
			<geom material='MatGnd' rgba='.6 .6 .5 1' solref='0.01 1' solimp='0.95 0.98 0.001' contype='1' condim='1' conaffinity='1' />
		</default>

		<default class='obstacle'>
			<geom material='MatGnd' rgba='.7 .4 .2 1' solref='0.01 1' solimp='0.95 0.98 0.001' contype='1' condim='1' conaffinity='1' />
		</default>

		<default class='object'>
			<geom rgba='0.4 0.5 0.9 1' solmix='0' density='400'/>
		</default>
	</default>


	<!--  ================= Kinematic Tree ================= /-->
    <worldbody>
		<light directional='true' cutoff='40' exponent='10' diffuse='.4 .4 .4' specular='.7 .7 .7' pos='0.9 0 1.5' dir='0 0 -1'/>

		<!--  ================= Table ================= /-->
		<geom name='tableTop' material='MatGnd' type='plane' pos='0.6 0 0' size='0.4 0.6 0.5' class='table'/>
		
		<body name='shift'>
			<!--  ================= Obstacle ================= /-->
			<body name='doorframe' pos='0.9 0 0' quat='1 0 0 0'>
				<geom type='box' class='obstacle' size='0.01 0.01 0.25' pos='0 0.16 0.25'/>
				<geom type='box' class='obstacle' size='0.01 0.01 0.25' pos='0 -0.16 0.25'/>
				<geom type='box' class='obstacle' size='0.01 0.17 0.01' pos='0 0 0.51'/>
				<geom type='box' class='obstacle' size='0.01 0.05 0.01' pos='-0.02 0.12 0.01'/>
				<body name='door' pos='0 0 0' quat='1 0 0 0'>
					<joint type='slide' pos='0 -0.13 0' axis='1 0 0' />
					<geom type='box' class='obstacle' size='0.01 0.14 0.248' pos='0 0 0.25' />
					
					<!--  ================= Object ================= /-->
					<body name='object' pos='0 0.12 0.25' quat='1 0 0 0'>
						<!--<joint pos='0 0 0' axis='1 0 0' limited='false' springdamper='0.001 2' springref='0.785'/>-->
						<joint pos='0 0 0' axis='1 0 0' range='0 0.786' springdamper='0.008 2' limited='true'/>
						<geom type='cylinder' size='0.014' fromto='0 0 0 -0.05 0 0' class='object' />
						<body name='bolt' pos='0 0 0' quat='0.924 0.383 0 0'>
							<geom type='box' size='0.0049 0.045 0.02' pos='-0.015 0.03 0' class='object' />
						</body>
						<geom type='capsule' size='0.014' fromto='-0.05 0 0 -0.05 -0.1 0' class='object' />
					</body>
				</body>
			</body>
		</body>
	</worldbody>

	<!--  ================= Sensors ================= /-->
	<sensor>
		<framepos name='obj_p' objtype='body' objname='object' />
		<framequat name='obj_r' objtype='body' objname='object' />
	</sensor>
</mujoco>
